Traceback (most recent call last):
  File "FLAG_apply_rules_NOTWORKING.py", line 294, in <module>
    main(args.json_filepath, args.text_filepath)
  File "FLAG_apply_rules_NOTWORKING.py", line 276, in main
    processed_test_set = process_data(data, rules, feature_bank, affixes)
  File "FLAG_apply_rules_NOTWORKING.py", line 229, in process_data
    generated_form = apply_rule(generated_form, rule, feature_bank)
  File "FLAG_apply_rules_NOTWORKING.py", line 63, in apply_rule
    print(u"Applying rule: {} to {} resulted in {}\n".format(rule, word, result_word))
UnicodeEncodeError: 'ascii' codec can't encode character u'\xd8' in position 44: ordinal not in range(128)
Traceback (most recent call last):
  File "FLAG_apply_rules_NOTWORKING.py", line 294, in <module>
    main(args.json_filepath, args.text_filepath)
  File "FLAG_apply_rules_NOTWORKING.py", line 276, in main
    processed_test_set = process_data(data, rules, feature_bank, affixes)
  File "FLAG_apply_rules_NOTWORKING.py", line 226, in process_data
    print(u"Generated form before applying rules: {}".format(generated_form))
UnicodeEncodeError: 'ascii' codec can't encode character u'\u014b' in position 42: ordinal not in range(128)
Traceback (most recent call last):
  File "FLAG_apply_rules_NOTWORKING.py", line 294, in <module>
    main(args.json_filepath, args.text_filepath)
  File "FLAG_apply_rules_NOTWORKING.py", line 276, in main
    processed_test_set = process_data(data, rules, feature_bank, affixes)
  File "FLAG_apply_rules_NOTWORKING.py", line 229, in process_data
    generated_form = apply_rule(generated_form, rule, feature_bank)
  File "FLAG_apply_rules_NOTWORKING.py", line 63, in apply_rule
    print(u"Applying rule: {} to {} resulted in {}\n".format(rule, word, result_word))
UnicodeEncodeError: 'ascii' codec can't encode character u'\xd8' in position 37: ordinal not in range(128)
Traceback (most recent call last):
  File "FLAG_apply_rules_NOTWORKING.py", line 294, in <module>
    main(args.json_filepath, args.text_filepath)
  File "FLAG_apply_rules_NOTWORKING.py", line 276, in main
    processed_test_set = process_data(data, rules, feature_bank, affixes)
  File "FLAG_apply_rules_NOTWORKING.py", line 226, in process_data
    print(u"Generated form before applying rules: {}".format(generated_form))
UnicodeEncodeError: 'ascii' codec can't encode character u'\u014b' in position 42: ordinal not in range(128)
Traceback (most recent call last):
  File "FLAG_apply_rules_NOTWORKING.py", line 294, in <module>
    main(args.json_filepath, args.text_filepath)
  File "FLAG_apply_rules_NOTWORKING.py", line 276, in main
    processed_test_set = process_data(data, rules, feature_bank, affixes)
  File "FLAG_apply_rules_NOTWORKING.py", line 229, in process_data
    generated_form = apply_rule(generated_form, rule, feature_bank)
  File "FLAG_apply_rules_NOTWORKING.py", line 63, in apply_rule
    print(u"Applying rule: {} to {} resulted in {}\n".format(rule, word, result_word))
UnicodeEncodeError: 'ascii' codec can't encode character u'\xd8' in position 31: ordinal not in range(128)
Traceback (most recent call last):
  File "FLAG_apply_rules_NOTWORKING.py", line 294, in <module>
    main(args.json_filepath, args.text_filepath)
  File "FLAG_apply_rules_NOTWORKING.py", line 276, in main
    processed_test_set = process_data(data, rules, feature_bank, affixes)
  File "FLAG_apply_rules_NOTWORKING.py", line 229, in process_data
    generated_form = apply_rule(generated_form, rule, feature_bank)
  File "FLAG_apply_rules_NOTWORKING.py", line 63, in apply_rule
    print(u"Applying rule: {} to {} resulted in {}\n".format(rule, word, result_word))
UnicodeEncodeError: 'ascii' codec can't encode character u'\xd8' in position 31: ordinal not in range(128)
Traceback (most recent call last):
  File "FLAG_apply_rules_NOTWORKING.py", line 294, in <module>
    main(args.json_filepath, args.text_filepath)
  File "FLAG_apply_rules_NOTWORKING.py", line 276, in main
    processed_test_set = process_data(data, rules, feature_bank, affixes)
  File "FLAG_apply_rules_NOTWORKING.py", line 229, in process_data
    generated_form = apply_rule(generated_form, rule, feature_bank)
  File "FLAG_apply_rules_NOTWORKING.py", line 63, in apply_rule
    print(u"Applying rule: {} to {} resulted in {}\n".format(rule, word, result_word))
UnicodeEncodeError: 'ascii' codec can't encode character u'\xd8' in position 42: ordinal not in range(128)
Traceback (most recent call last):
  File "FLAG_apply_rules_NOTWORKING.py", line 294, in <module>
    main(args.json_filepath, args.text_filepath)
  File "FLAG_apply_rules_NOTWORKING.py", line 276, in main
    processed_test_set = process_data(data, rules, feature_bank, affixes)
  File "FLAG_apply_rules_NOTWORKING.py", line 229, in process_data
    generated_form = apply_rule(generated_form, rule, feature_bank)
  File "FLAG_apply_rules_NOTWORKING.py", line 63, in apply_rule
    print(u"Applying rule: {} to {} resulted in {}\n".format(rule, word, result_word))
UnicodeEncodeError: 'ascii' codec can't encode character u'\xd8' in position 37: ordinal not in range(128)
Traceback (most recent call last):
  File "FLAG_apply_rules_NOTWORKING.py", line 294, in <module>
    main(args.json_filepath, args.text_filepath)
  File "FLAG_apply_rules_NOTWORKING.py", line 276, in main
    processed_test_set = process_data(data, rules, feature_bank, affixes)
  File "FLAG_apply_rules_NOTWORKING.py", line 229, in process_data
    generated_form = apply_rule(generated_form, rule, feature_bank)
  File "FLAG_apply_rules_NOTWORKING.py", line 63, in apply_rule
    print(u"Applying rule: {} to {} resulted in {}\n".format(rule, word, result_word))
UnicodeEncodeError: 'ascii' codec can't encode character u'\xd8' in position 28: ordinal not in range(128)
Traceback (most recent call last):
  File "FLAG_apply_rules_NOTWORKING.py", line 294, in <module>
    main(args.json_filepath, args.text_filepath)
  File "FLAG_apply_rules_NOTWORKING.py", line 276, in main
    processed_test_set = process_data(data, rules, feature_bank, affixes)
  File "FLAG_apply_rules_NOTWORKING.py", line 229, in process_data
    generated_form = apply_rule(generated_form, rule, feature_bank)
  File "FLAG_apply_rules_NOTWORKING.py", line 63, in apply_rule
    print(u"Applying rule: {} to {} resulted in {}\n".format(rule, word, result_word))
UnicodeEncodeError: 'ascii' codec can't encode character u'\xd8' in position 39: ordinal not in range(128)
Traceback (most recent call last):
  File "FLAG_apply_rules_NOTWORKING.py", line 333, in <module>
    main(args.json_filepath, args.text_filepath)
  File "FLAG_apply_rules_NOTWORKING.py", line 315, in main
    processed_test_set = process_data(data, rules, feature_bank, affixes)
  File "FLAG_apply_rules_NOTWORKING.py", line 259, in process_data
    affix_to_apply = ' '.join(list(affixes[i][1]))
IndexError: list index out of range
Traceback (most recent call last):
  File "FLAG_apply_rules_NOTWORKING.py", line 333, in <module>
    main(args.json_filepath, args.text_filepath)
  File "FLAG_apply_rules_NOTWORKING.py", line 315, in main
    processed_test_set = process_data(data, rules, feature_bank, affixes)
  File "FLAG_apply_rules_NOTWORKING.py", line 259, in process_data
    affix_to_apply = ' '.join(list(affixes[i][1]))
IndexError: list index out of range
Traceback (most recent call last):
  File "FLAG_apply_rules_NOTWORKING.py", line 333, in <module>
    main(args.json_filepath, args.text_filepath)
  File "FLAG_apply_rules_NOTWORKING.py", line 315, in main
    processed_test_set = process_data(data, rules, feature_bank, affixes)
  File "FLAG_apply_rules_NOTWORKING.py", line 259, in process_data
    affix_to_apply = ' '.join(list(affixes[i][1]))
IndexError: list index out of range
Traceback (most recent call last):
  File "FLAG_apply_rules_NOTWORKING.py", line 333, in <module>
    main(args.json_filepath, args.text_filepath)
  File "FLAG_apply_rules_NOTWORKING.py", line 315, in main
    processed_test_set = process_data(data, rules, feature_bank, affixes)
  File "FLAG_apply_rules_NOTWORKING.py", line 259, in process_data
    affix_to_apply = ' '.join(list(affixes[i][1]))
IndexError: list index out of range
Traceback (most recent call last):
  File "FLAG_apply_rules_NOTWORKING.py", line 337, in <module>
    main(args.json_filepath, args.text_filepath)
  File "FLAG_apply_rules_NOTWORKING.py", line 319, in main
    processed_test_set = process_data(data, rules, feature_bank, affixes)
  File "FLAG_apply_rules_NOTWORKING.py", line 263, in process_data
    affix_to_apply = ' '.join(list(affixes[i][1]))
IndexError: list index out of range
Traceback (most recent call last):
  File "FLAG_apply_rules_NOTWORKING.py", line 337, in <module>
    main(args.json_filepath, args.text_filepath)
  File "FLAG_apply_rules_NOTWORKING.py", line 319, in main
    processed_test_set = process_data(data, rules, feature_bank, affixes)
  File "FLAG_apply_rules_NOTWORKING.py", line 263, in process_data
    affix_to_apply = ' '.join(list(affixes[i][1]))
IndexError: list index out of range
Traceback (most recent call last):
  File "FLAG_apply_rules_NOTWORKING.py", line 337, in <module>
    main(args.json_filepath, args.text_filepath)
  File "FLAG_apply_rules_NOTWORKING.py", line 319, in main
    processed_test_set = process_data(data, rules, feature_bank, affixes)
  File "FLAG_apply_rules_NOTWORKING.py", line 263, in process_data
    affix_to_apply = ' '.join(list(affixes[i][1]))
IndexError: list index out of range
Traceback (most recent call last):
  File "FLAG_apply_rules_NOTWORKING.py", line 337, in <module>
    main(args.json_filepath, args.text_filepath)
  File "FLAG_apply_rules_NOTWORKING.py", line 319, in main
    processed_test_set = process_data(data, rules, feature_bank, affixes)
  File "FLAG_apply_rules_NOTWORKING.py", line 263, in process_data
    affix_to_apply = ' '.join(list(affixes[i][1]))
IndexError: list index out of range
